Workbook

Sheet Read me
B2: SharePix unit economics
B3: Rebuilt September 2026 for the current lineup: one free event per account, one paid plan at $79.
B5: This is a rebuild, not an edit
B6: The previous model was not available to work from. Everything here was derived fresh from the
B7: codebase and from published cloud pricing. Treat any figure you recognise from the old model as a
B8: coincidence rather than a carried-forward value.
B10: Why the old model could not be patched
B11: It predates three changes that each move the answer:
B12: 1. Photos are now UNLIMITED on the paid plan. The old model multiplied a fixed cap by a cost
B13: per photo. There is no cap to multiply, so cost per event is now a distribution, not a number.
B14: That is why this workbook leads with a break-even grid instead of a single margin figure.
B15: 2. A free tier exists. Its cost is real and is carried by paid events, so the number that matters
... B39: See "Dual storage" on the Unit economics sheet for what that costs and what could be done.

Sheet Assumptions
A1: Assumptions
A2: Blue cells are inputs. Yellow shading means the value is an estimate and should be replaced with a measurement.
A4: Assumption | B4: Value | C4: Unit | D4: Confidence | E4: Source / note
A5: PRICING
A6: Paid plan price | B6: 79 | C6: USD | D6: CODE | E6: lib/pricing.ts — tier "plus", displayed as Full Event
A7: Free plan price | B7: 0 | C7: USD | D7: CODE | E7: lib/pricing.ts — tier "free", one per account
A8: Upload window extension price | B8: 40 | C8: USD | D8: CODE | E8: extensionPrice() — half the plan price, rounded
A9: PLAN LIMITS
A10: Paid photo limit | B10: 0 | C10: photos | D10: CODE | E10: photoLimit is null = unlimited. 0 here means "no cap"; the grid below models the range
A11: Paid video limit | B11: 30 | C11: videos | D11: CODE | E11: lib/pricing.ts
A12: Max video file size | B12: 250 | C12: MB | D12: CODE | E12: MAX_VIDEO_SIZE_BYTES in lib/validation.ts
A13: Free photo limit | B13: 50 | C13: photos | D13: CODE | E13: lib/pricing.ts
A14: Free video limit | B14: 1 | C14: videos | D14: CODE | E14: lib/pricing.ts
A15: RETENTION — the main cost driver
A16: Upload window | B16: 60 | C16: days | D16: CODE | E16: UPLOAD_WINDOW_DAYS
A17: Paid gallery retention | B17: 365 | C17: days | D17: CODE | E17: GALLERY_MONTHS = 12
A18: Archive before deletion | B18: 90 | C18: days | D18: CODE | E18: ARCHIVE_DAYS
A19: Reclaim grace margin | B19: 7 | C19: days | D19: CODE | E19: GRACE_DAYS in lib/storageReclaim.ts
A20: Free gallery retention | B20: 30 | C20: days | D20: CODE | E20: lib/pricing.ts
A21: S3 copy retention | B21: 90 | C21: days | D21: CODE | E21: S3_COPY_RETENTION_DAYS in amplify/backend.ts. Was 800; shortened once prints moved to R2
A22: MEDIA SIZES
A23: Average original photo | B23: 3.8 | C23: MB | D23: ESTIMATE | E23: Modern phone JPEG. Replace with the mean of MediaObject.bytes — the data exists
A24: Average preview (1280px q0.68) | B24: 0.22 | C24: MB | D24: ESTIMATE | E24: Derived from PREVIEW_MAX_DIMENSION / PREVIEW_JPEG_QUALITY in lib/mediaPreview.ts
A25: Average thumbnail (480px q0.5) | B25: 0.03 | C25: MB | D25: ESTIMATE | E25: Derived from THUMB_MAX_DIMENSION / THUMB_JPEG_QUALITY
A26: Average video file | B26: 60 | C26: MB | D26: ESTIMATE | E26: Well under the 250 MB ceiling; most guest clips are short. Replace with measured mean
A27: EVENT SHAPE
A28: Photos per paid event (central case) | B28: 700 | C28: photos | D28: ESTIMATE | E28: The number this whole model is most sensitive to. Break-even sheet varies it
A29: Videos per paid event | B29: 8 | C29: videos | D29: ESTIMATE | E29: Against a limit of 30
A30: Photos per free event | B30: 50 | C30: photos | D30: CODE | E30: Free events hit their cap; that is what the cap is for
A31: Full-res downloads per photo | B31: 0.9 | C31: downloads | D31: ESTIMATE | E31: Guest downloads are included on every plan, so this drives egress
A32: Preview views per photo | B32: 14 | C32: views | D32: ESTIMATE | E32: Gallery browsing over 12 months
A33: CLOUD RATES
A34: R2 storage | B34: 0.015 | C34: USD/GB-mo | D34: PUBLISHED | E34: Cloudflare R2 standard storage
A35: R2 egress | B35: 0 | C35: USD/GB | D35: PUBLISHED | E35: Zero. This is the entire reason for the hybrid — see docs/r2-hybrid.md
A36: S3 storage | B36: 0.023 | C36: USD/GB-mo | D36: PUBLISHED | E36: S3 Standard, us-east-1
A37: S3 egress (mirror copy-out, one-off) | B37: 0.09 | C37: USD/GB | D37: PUBLISHED | E37: Paid once per object when sanitize-upload copies it to R2
A38: Lambda + DynamoDB + AppSync per event | B38: 0.12 | C38: USD | D38: ESTIMATE | E38: Upload processing, Rekognition screening, scheduled jobs, API calls
A39: SES email per event | B39: 0.02 | C39: USD | D39: ESTIMATE | E39: Reminders at 60/30/7 days, survey and rating invites
A40: COMMERCIAL
A41: Stripe percentage fee | B41: 0.029 | C41: % of price | D41: PUBLISHED | E41: Standard card rate
...

Sheet Unit economics
A1: Per-event unit economics
A2: One event, over its whole life. Storage is charged for the ~17 months it is actually held, not for the length of the party.
B4: Full Event ($79) | C4: Free event | D4: Note
A5: VOLUME
A6: Photos | B6: =Assumptions!$B$28 | C6: =Assumptions!$B$30 | D6: Paid is the central case only — the Break-even sheet varies it, because there is no cap to anchor on
A7: Videos | B7: =Assumptions!$B$29 | C7: =Assumptions!$B$14 | D7: Video is capped on both plans
A9: STORED VOLUME (GB)
A10: Originals | B10: =B6*Assumptions!$B$23/1024 | C10: =C6*Assumptions!$B$23/1024 | D10: Full-resolution files. Guest downloads serve these, which is why egress tracks them
A11: Previews | B11: =B6*Assumptions!$B$24/1024 | C11: =C6*Assumptions!$B$24/1024 | D11: 1280px, quality 0.68 — what the gallery actually displays
A12: Thumbnails | B12: =B6*Assumptions!$B$25/1024 | C12: =C6*Assumptions!$B$25/1024 | D12: 480px, quality 0.5
A13: Video | B13: =B7*Assumptions!$B$26/1024 | C13: =C7*Assumptions!$B$26/1024 | D13: Never resized. Served at full size on every play — the reason video stays capped while photos did not
A14: Total stored per event | B14: =SUM(B10:B13) | C14: =SUM(C10:C13) | D14: GB
A16: HOW LONG IT IS HELD
A17: Customer-visible life (months) | B17: =(Assumptions!$B$16+Assumptions!$B$17+Assumptions!$B$18+Assumptions!$B$19)/30.44 | C17: =(Assumptions!$B$16+Assumptions!$B$20+Assumptions!$B$18+Assumptions!$B$19)/30.44 | D17: Window + gallery + archive + grace. What reclaim-storage enforces
A18: S3 copy held (months) | B18: =Assumptions!$B$21/30.44 | C18: =Assumptions!$B$21/30.44 | D18: The 800-day backstop. Not shortened when the event is reclaimed — see Dual storage below
A20: REVENUE
A21: List price | B21: =Assumptions!$B$6 | C21: =Assumptions!$B$7
A22: Less: Stripe fees | B22: =-(B21*Assumptions!$B$41+Assumptions!$B$42) | C22: =0 | D22: A free event never reaches Stripe at all — priceableTier is membership of TIER_PRICING
A23: Less: expected Guest Upload Promise refund | B23: =-B21*Assumptions!$B$43 | C23: =0
A24: Net revenue | B24: =SUM(B21:B23) | C24: =SUM(C21:C23)
A26: COST
A27: R2 storage | B27: =B14*B17*Assumptions!$B$34 | C27: =C14*C17*Assumptions!$B$34 | D27: Serves every read
A28: S3 storage (second copy) | B28: =B14*B18*Assumptions!$B$36 | C28: =C14*C18*Assumptions!$B$36 | D28: The duplicate. Larger than the R2 line because it is both dearer per GB and held longer
A29: S3 egress — one-off mirror copy | B29: =B14*Assumptions!$B$37 | C29: =C14*Assumptions!$B$37 | D29: Paid once per object when sanitize-upload copies it to R2
A30: Guest download egress | B30: =B10*Assumptions!$B$31*Assumptions!$B$35 | C30: =C10*Assumptions!$B$31*Assumptions!$B$35 | D30: Zero, because R2 charges nothing for egress. On S3 this was the single largest line
A31: Compute, database and API | B31: =Assumptions!$B$38 | C31: =Assumptions!$B$38 | D31: Upload processing, Rekognition screening, scheduled jobs
A32: Email | B32: =Assumptions!$B$39 | C32: =Assumptions!$B$39 | D32: Expiry reminders, survey and rating invites
A33: Research gift card (expected) | B33: =Assumptions!$B$44*Assumptions!$B$45 | C33: =0 | D33: Only successful events are invited, and the card is bought by hand
A34: Total cost per event | B34: =SUM(B27:B33) | C34: =SUM(C27:C33)
A36: RESULT
A37: Gross margin per event | B37: =B24-B34 | C37: =C24-C34
A38: Gross margin % | B38: =IFERROR(B37/B24,0) | C38: n/a
A40: DUAL STORAGE — what the second copy costs
A41: S3 duplicate as % of total cost | B41: =IFERROR(B28/B34,0) | D41: Objects are written to S3, mirrored to R2, and R2 serves every read. The S3 copy is never removed early.
A42: Saving if S3 expired 30 days after mirroring | B42: =B14*(B18-1)*Assumptions!$B$36 | D42: Not a recommendation yet: S3 is the write path and the re-mirror source. Worth costing properly before acting.
A43: ...as % of the $79 price | B43: =IFERROR(B42/B21,0)
A45: The number to watch
A46: Photos per event is the only input with no ceiling, so it is the only one that can turn this negative on its own.
A47: The Break-even sheet is that question asked directly. Everything else here moves the answer by cents.

Sheet Break-even
A1: Break-even: how many photos before a $79 event stops paying
A2: Unlimited photos removed the cap the old model multiplied against. This grid is what replaced it.
A3: Rows: photos uploaded. Columns: what R2 might charge for egress. Each cell is gross margin in dollars.
A4: Downloads per photo is an input on Assumptions; it only bites in the columns where egress is not free.
A6: Photos \ R2 egress per GB | B6: $0.00 (today) | C6: $0.005 | D6: $0.010 | E6: $0.020 | F6: $0.045 | G6: $0.090 (S3 parity)
A7: rate used -> | B7: 0 | C7: 0.005 | D7: 0.01 | E7: 0.02 | F7: 0.045 | G7: 0.09
A8: 200 | B8: =(Assumptions!$B$6*(1-Assumptions!$B$41-Assumptions!$B$43)-Assumptions!$B$42)-(Assumptions!$B$38+Assumptions!$B$39+Assumptions!$B$44*Assumptions!$B$45)-(($A8*(Assumptions!$B$23+Assumptions!$B$24+Assumptions!$B$25)/1024)+(Assumptions!$B$29*Assumptions!$B$26/1024))*((Assumptions!$B$16+Assumptions!$B$17+Assumptions!$B$18+Assumptions!$B$19)/30.44)*Assumptions!$B$34-(($A8*(Assumptions!$B$23+Assumptions!$B$24+Assumptions!$B$25)/1024)+(Assumptions!$B$29*Assumptions!$B$26/1024))*(Assumptions!$B$21/30.44)*Assumptions!$B$36-(($A8*(Assumptions!$B$23+Assumptions!$B$24+Assumptions!$B$25)/1024)+(Assumptions!$B$29*Assumptions!$B$26/1024))*Assumptions!$B$37-(($A8*Assumptions!$B$23/1024)*Assumptions!$B$31+($A8*Assumptions!$B$24/1024)*Assumptions!$B$32)*B$7 | C8: =(Assumptions!$B$6*(1-Assumptions!$B$41-Assumptions!$B$43)-Assumptions!$B$42)-(Assumptions!$B$38+Assumptions!$B$39+Assumptions!$B$44*Assumptions!$B$45)-(($A8*(Assumptions!$B$23+Assumptions!$B$24+Assumptions!$B$25)/1024)+(Assumptions!$B$29*Assumptions!$B$26/1024))*((Assumptions!$B$16+Assumptions!$B$17+Assumptions!$B$18+Assumptions!$B$19)/30.44)*Assumptions!$B$34-(($A8*(Assumptions!$B$23+Assumptions!$B$24+Assumptions!$B$25)/1024)+(Assumptions!$B$29*Assumptions!$B$26/1024))*(Assumptions!$B$21/30.44)*Assumptions!$B$36-(($A8*(Assumptions!$B$23+Assumptions!$B$24+Assumptions!$B$25)/1024)+(Assumptions!$B$29*Assumptions!$B$26/1024))*Assumptions!$B$37-(($A8*Assumptions!$B$23/1024)*Assumptions!$B$31+($A8*Assumptions!$B$24/1024)*Assumptions!$B$32)*C$7 | D8: =(Assumptions!$B$6*(1-Assumptions!$B$41-Assumptions!$B$43)-Assumptions!$B$42)-(Assumptions!$B$38+Assumptions!$B$39+Assumptions!$B$44*Assumptions!$B$45)-(($A8*(Assumptions!$B$23+Assumptions!$B$24+Assumptions!$B$25)/1024)+(Assumptions!$B$29*Assumptions!$B$26/1024))*((Assumptions!$B$16+Assumptions!$B$17+Assumptions!$B$18+Assumptions!$B$19)/30.44)*Assumptions!$B$34-(($A8*(Assumptions!$B$23+Assumptions!$B$24+Assumptions!$B$25)/1024)+(Assumptions!$B$29*Assumptions!$B$26/1024))*(Assumptions!$B$21/30.44)*Assumptions!$B$36-(($A8*(Assumptions!$B$23+Assumptions!$B$24+Assumptions!$B$25)/1024)+(Assumptions!$B$29*Assumptions!$B$26/1024))*Assumptions!$B$37-(($A8*Assumptions!$B$23/1024)*Assumptions!$B$31+($A8*Assumptions!$B$24/1024)*Assumptions!$B$32)*D$7 | E8: =(Assumptions!$B$6*(1-Assumptions!$B$41-Assumptions!$B$43)-Assumptions!$B$42)-(Assumptions!$B$38+Assumptions!$B$39+Assumptions!$B$44*Assumptions!$B$45)-(($A8*(Assumptions!$B$23+Assumptions!$B$24+Assumptions!$B$25)/1024)+(Assumptions!$B$29*Assumptions!$B$26/1024))*((Assumptions!$B$16+Assumptions!$B$17+Assumptions!$B$18+Assumptions!$B$19)/30.44)*Assumptions!$B$34-(($A8*(Assumptions!$B$23+Assumptions!$B$24+Assumptions!$B$25)/1024)+(Assumptions!$B$29*Assumptions!$B$26/1024))*(Assumptions!$B$21/30.44)*Assumptions!$B$36-(($A8*(Assumptions!$B$23+Assumptions!$B$24+Assumptions!$B$25)/1024)+(Assumptions!$B$29*Assumptions!$B$26/1024))*Assumptions!$B$37-(($A8*Assumptions!$B$23/1024)*Assumptions!$B$31+($A8*Assumptions!$B$24/1024)*Assumptions!$B$32)*E$7 | F8: =(Assumptions!$B$6*(1-Assumptions!$B$41-Assumptions!$B$43)-Assumptions!$B$42)-(Assumptions!$B$38+Assumptions!$B$39+Assumptions!$B$44*Assumptions!$B$45)-(($A8*(Assumptions!$B$23+Assumptions!$B$24+Assumptions!$B$25)/1024)+(Assumptions!$B$29*Assumptions!$B$26/1024))*((Assumptions!$B$16+Assumptions!$B$17+Assumptions!$B$18+Assumptions!$B$19)/30.44)*Assumptions!$B$34-(($A8*(Assumptions!$B$23+Assumptions!$B$24+Assumptions!$B$25)/1024)+(Assumptions!$B$29*Assumptions!$B$26/1024))*(Assumptions!$B$21/30.44)*Assumptions!$B$36-(($A8*(Assumptions!$B$23+Assumptions!$B$24+Assumptions!$B$25)/1024)+(Assumptions!$B$29*Assumptions!$B$26/1024))*Assumptions!$B$37-(($A8*Assumptions!$B$23/1024)*Assumptions!$B$31+($A8*Assumptions!$B$24/1024)*Assumptions!$B$32)*F$7 | G8: =(Assumptions!$B$6*(1-Assumptions!$B$41-Assumptions!$B$43)-Assumptions!$B$42)-(Assumptions!$B$38+Assumptions!$B$39+Assumptions!$B$44*Assumptions!$B$45)-(($A8*(Assumptions!$B$23+Assumptions!$B$24+Assumptions!$B$25)/1024)+(Assumptions!$B$29*Assumptions!$B$26/1024))*((Assumptions!$B$16+Assumptions!$B$17+Assumptions!$B$18+Assumptions!$B$19)/30.44)*Assumptions!$B$34-(($A8*(Assumptions!$B$23+Assumptions!$B$24+Assumptions!$B$25)/1024)+(Assumptions!$B$29*Assumptions!$B$26/1024))*(Assumptions!$B$21/30.44)*Assumptions!$B$36-(($A8*(Assumptions!$B$23+Assumptions!$B$24+Assumptions!$B$25)/1024)+(Assumptions!$B$29*Assumptions!$B$26/1024))*Assumptions!$B$37-(($A8*Assumptions!$B$23/1024)*Assumptions!$B$31+($A8*Assumptions!$B$24/1024)*Assumptions!$B$32)*G$7
A9: 500 | B9: =(Assumptions!$B$6*(1-Assumptions!$B$41-Assumptions!$B$43)-Assumptions!$B$42)-(Assumptions!$B$38+Assumptions!$B$39+Assumptions!$B$44*Assumptions!$B$45)-(($A9*(Assumptions!$B$23+Assumptions!$B$24+Assumptions!$B$25)/1024)+(Assumptions!$B$29*Assumptions!$B$26/1024))*((Assumptions!$B$16+Assumptions!$B$17+Assumptions!$B$18+Assumptions!$B$19)/30.44)*Assumptions!$B$34-(($A9*(Assumptions!$B$23+Assumptions!$B$24+Assumptions!$B$25)/1024)+(Assumptions!$B$29*Assumptions!$B$26/1024))*(Assumptions!$B$21/30.44)*Assumptions!$B$36-(($A9*(Assumptions!$B$23+Assumptions!$B$24+Assumptions!$B$25)/1024)+(Assumptions!$B$29*Assumptions!$B$26/1024))*Assumptions!$B$37-(($A9*Assumptions!$B$23/1024)*Assumptions!$B$31+($A9*Assumptions!$B$24/1024)*Assumptions!$B$32)*B$7 | C9: =(Assumptions!$B$6*(1-Assumptions!$B$41-Assumptions!$B$43)-Assumptions!$B$42)-(Assumptions!$B$38+Assumptions!$B$39+Assumptions!$B$44*Assumptions!$B$45)-(($A9*(Assumptions!$B$23+Assumptions!$B$24+Assumptions!$B$25)/1024)+(Assumptions!$B$29*Assumptions!$B$26/1024))*((Assumptions!$B$16+Assumptions!$B$17+Assumptions!$B$18+Assumptions!$B$19)/30.44)*Assumptions!$B$34-(($A9*(Assumptions!$B$23+Assumptions!$B$24+Assumptions!$B$25)/1024)+(Assumptions!$B$29*Assumptions!$B$26/1024))*(Assumptions!$B$21/30.44)*Assumptions!$B$36-(($A9*(Assumptions!$B$23+Assumptions!$B$24+Assumptions!$B$25)/1024)+(Assumptions!$B$29*Assumptions!$B$26/1024))*Assumptions!$B$37-(($A9*Assumptions!$B$23/1024)*Assumptions!$B$31+($A9*Assumptions!$B$24/1024)*Assumptions!$B$32)*C$7 | D9: =(Assumptions!$B$6*(1-Assumptions!$B$41-Assumptions!$B$43)-Assumptions!$B$42)-(Assumptions!$B$38+Assumptions!$B$39+Assumptions!$B$44*Assumptions!$B$45)-(($A9*(Assumptions!$B$23+Assumptions!$B$24+Assumptions!$B$25)/1024)+(Assumptions!$B$29*Assumptions!$B$26/1024))*((Assumptions!$B$16+Assumptions!$B$17+Assumptions!$B$18+Assumptions!$B$19)/30.44)*Assumptions!$B$34-(($A9*(Assumptions!$B$23+Assumptions!$B$24+Assumptions!$B$25)/1024)+(Assumptions!$B$29*Assumptions!$B$26/1024))*(Assumptions!$B$21/30.44)*Assumptions!$B$36-(($A9*(Assumptions!$B$23+Assumptions!$B$24+Assumptions!$B$25)/1024)+(Assumptions!$B$29*Assumptions!$B$26/1024))*Assumptions!$B$37-(($A9*Assumptions!$B$23/1024)*Assumptions!$B$31+($A9*Assumptions!$B$24/1024)*Assumptions!$B$32)*D$7 | E9: =(Assumptions!$B$6*(1-Assumptions!$B$41-Assumptions!$B$43)-Assumptions!$B$42)-(Assumptions!$B$38+Assumptions!$B$39+Assumptions!$B$44*Assumptions!$B$45)-(($A9*(Assumptions!$B$23+Assumptions!$B$24+Assumptions!$B$25)/1024)+(Assumptions!$B$29*Assumptions!$B$26/1024))*((Assumptions!$B$16+Assumptions!$B$17+Assumptions!$B$18+Assumptions!$B$19)/30.44)*Assumptions!$B$34-(($A9*(Assumptions!$B$23+Assumptions!$B$24+Assumptions!$B$25)/1024)+(Assumptions!$B$29*Assumptions!$B$26/1024))*(Assumptions!$B$21/30.44)*Assumptions!$B$36-(($A9*(Assumptions!$B$23+Assumptions!$B$24+Assumptions!$B$25)/1024)+(Assumptions!$B$29*Assumptions!$B$26/1024))*Assumptions!$B$37-(($A9*Assumptions!$B$23/1024)*Assumptions!$B$31+($A9*Assumptions!$B$24/1024)*Assumptions!$B$32)*E$7 | F9: =(Assumptions!$B$6*(1-Assumptions!$B$41-Assumptions!$B$43)-Assumptions!$B$42)-(Assumptions!$B$38+Assumptions!$B$39+Assumptions!$B$44*Assumptions!$B$45)-(($A9*(Assumptions!$B$23+Assumptions!$B$24+Assumptions!$B$25)/1024)+(Assumptions!$B$29*Assumptions!$B$26/1024))*((Assumptions!$B$16+Assumptions!$B$17+Assumptions!$B$18+Assumptions!$B$19)/30.44)*Assumptions!$B$34-(($A9*(Assumptions!$B$23+Assumptions!$B$24+Assumptions!$B$25)/1024)+(Assumptions!$B$29*Assumptions!$B$26/1024))*(Assumptions!$B$21/30.44)*Assumptions!$B$36-(($A9*(Assumptions!$B$23+Assumptions!$B$24+Assumptions!$B$25)/1024)+(Assumptions!$B$29*Assumptions!$B$26/1024))*Assumptions!$B$37-(($A9*Assumptions!$B$23/1024)*Assumptions!$B$31+($A9*Assumptions!$B$24/1024)*Assumptions!$B$32)*F$7 | G9: =(Assumptions!$B$6*(1-Assumptions!$B$41-Assumptions!$B$43)-Assumptions!$B$42)-(Assumptions!$B$38+Assumptions!$B$39+Assumptions!$B$44*Assumptions!$B$45)-(($A9*(Assumptions!$B$23+Assumptions!$B$24+Assumptions!$B$25)/1024)+(Assumptions!$B$29*Assumptions!$B$26/1024))*((Assumptions!$B$16+Assumptions!$B$17+Assumptions!$B$18+Assumptions!$B$19)/30.44)*Assumptions!$B$34-(($A9*(Assumptions!$B$23+Assumptions!$B$24+Assumptions!$B$25)/1024)+(Assumptions!$B$29*Assumptions!$B$26/1024))*(Assumptions!$B$21/30.44)*Assumptions!$B$36-(($A9*(Assumptions!$B$23+Assumptions!$B$24+Assumptions!$B$25)/1024)+(Assumptions!$B$29*Assumptions!$B$26/1024))*Assumptions!$B$37-(($A9*Assumptions!$B$23/1024)*Assumptions!$B$31+($A9*Assumptions!$B$24/1024)*Assumptions!$B$32)*G$7
A10: 1000 | B10: =(Assumptions!$B$6*(1-Assumptions!$B$41-Assumptions!$B$43)-Assumptions!$B$42)-(Assumptions!$B$38+Assumptions!$B$39+Assumptions!$B$44*Assumptions!$B$45)-(($A10*(Assumptions!$B$23+Assumptions!$B$24+Assumptions!$B$25)/1024)+(Assumptions!$B$29*Assumptions!$B$26/1024))*((Assumptions!$B$16+Assumptions!$B$17+Assumptions!$B$18+Assumptions!$B$19)/30.44)*Assumptions!$B$34-(($A10*(Assumptions!$B$23+Assumptions!$B$24+Assumptions!$B$25)/1024)+(Assumptions!$B$29*Assumptions!$B$26/1024))*(Assumptions!$B$21/30.44)*Assumptions!$B$36-(($A10*(Assumptions!$B$23+Assumptions!$B$24+Assumptions!$B$25)/1024)+(Assumptions!$B$29*Assumptions!$B$26/1024))*Assumptions!$B$37-(($A10*Assumptions!$B$23/1024)*Assumptions!$B$31+($A10*Assumptions!$B$24/1024)*Assumptions!$B$32)*B$7 | C10: =(Assumptions!$B$6*(1-Assumptions!$B$41-Assumptions!$B$43)-Assumptions!$B$42)-(Assumptions!$B$38+Assumptions!$B$39+Assumptions!$B$44*Assumptions!$B$45)-(($A10*(Assumptions!$B$23+Assumptions!$B$24+Assumptions!$B$25)/1024)+(Assumptions!$B$29*Assumptions!$B$26/1024))*((Assumptions!$B$16+Assumptions!$B$17+Assumptions!$B$18+Assumptions!$B$19)/30.44)*Assumptions!$B$34-(($A10*(Assumptions!$B$23+Assumptions!$B$24+Assumptions!$B$25)/1024)+(Assumptions!$B$29*Assumptions!$B$26/1024))*(Assumptions!$B$21/30.44)*Assumptions!$B$36-(($A10*(Assumptions!$B$23+Assumptions!$B$24+Assumptions!$B$25)/1024)+(Assumptions!$B$29*Assumptions!$B$26/1024))*Assumptions!$B$37-(($A10*Assumptions!$B$23/1024)*Assumptions!$B$31+($A10*Assumptions!$B$24/1024)*Assumptions!$B$32)*C$7 | D10: =(Assumptions!$B$6*(1-Assumptions!$B$41-Assumptions!$B$43)-Assumptions!$B$42)-(Assumptions!$B$38+Assumptions!$B$39+Assumptions!$B$44*Assumptions!$B$45)-(($A10*(Assumptions!$B$23+Assumptions!$B$24+Assumptions!$B$25)/1024)+(Assumptions!$B$29*Assumptions!$B$26/1024))*((Assumptions!$B$16+Assumptions!$B$17+Assumptions!$B$18+Assumptions!$B$19)/30.44)*Assumptions!$B$34-(($A10*(Assumptions!$B$23+Assumptions!$B$24+Assumptions!$B$25)/1024)+(Assumptions!$B$29*Assumptions!$B$26/1024))*(Assumptions!$B$21/30.44)*Assumptions!$B$36-(($A10*(Assumptions!$B$23+Assumptions!$B$24+Assumptions!$B$25)/1024)+(Assumptions!$B$29*Assumptions!$B$26/1024))*Assumptions!$B$37-(($A10*Assumptions!$B$23/1024)*Assumptions!$B$31+($A10*Assumptions!$B$24/1024)*Assumptions!$B$32)*D$7 | E10: =(Assumptions!$B$6*(1-Assumptions!$B$41-Assumptions!$B$43)-Assumptions!$B$42)-(Assumptions!$B$38+Assumptions!$B$39+Assumptions!$B$44*Assumptions!$B$45)-(($A10*(Assumptions!$B$23+Assumptions!$B$24+Assumptions!$B$25)/1024)+(Assumptions!$B$29*Assumptions!$B$26/1024))*((Assumptions!$B$16+Assumptions!$B$17+Assumptions!$B$18+Assumptions!$B$19)/30.44)*Assumptions!$B$34-(($A10*(Assumptions!$B$23+Assumptions!$B$24+Assumptions!$B$25)/1024)+(Assumptions!$B$29*Assumptions!$B$26/1024))*(Assumptions!$B$21/30.44)*Assumptions!$B$36-(($A10*(Assumptions!$B$23+Assumptions!$B$24+Assumptions!$B$25)/1024)+(Assumptions!$B$29*Assumptions!$B$26/1024))*Assumptions!$B$37-(($A10*Assumptions!$B$23/1024)*Assumptions!$B$31+($A10*Assumptions!$B$24/1024)*Assumptions!$B$32)*E$7 | F10: =(Assumptions!$B$6*(1-Assumptions!$B$41-Assumptions!$B$43)-Assumptions!$B$42)-(Assumptions!$B$38+Assumptions!$B$39+Assumptions!$B$44*Assumptions!$B$45)-(($A10*(Assumptions!$B$23+Assumptions!$B$24+Assumptions!$B$25)/1024)+(Assumptions!$B$29*Assumptions!$B$26/1024))*((Assumptions!$B$16+Assumptions!$B$17+Assumptions!$B$18+Assumptions!$B$19)/30.44)*Assumptions!$B$34-(($A10*(Assumptions!$B$23+Assumptions!$B$24+Assumptions!$B$25)/1024)+(Assumptions!$B$29*Assumptions!$B$26/1024))*(Assumptions!$B$21/30.44)*Assumptions!$B$36-(($A10*(Assumptions!$B$23+Assumptions!$B$24+Assumptions!$B$25)/1024)+(Assumptions!$B$29*Assumptions!$B$26/1024))*Assumptions!$B$37-(($A10*Assumptions!$B$23/1024)*Assumptions!$B$31+($A10*Assumptions!$B$24/1024)*Assumptions!$B$32)*F$7 | G10: =(Assumptions!$B$6*(1-Assumptions!$B$41-Assumptions!$B$43)-Assumptions!$B$42)-(Assumptions!$B$38+Assumptions!$B$39+Assumptions!$B$44*Assumptions!$B$45)-(($A10*(Assumptions!$B$23+Assumptions!$B$24+Assumptions!$B$25)/1024)+(Assumptions!$B$29*Assumptions!$B$26/1024))*((Assumptions!$B$16+Assumptions!$B$17+Assumptions!$B$18+Assumptions!$B$19)/30.44)*Assumptions!$B$34-(($A10*(Assumptions!$B$23+Assumptions!$B$24+Assumptions!$B$25)/1024)+(Assumptions!$B$29*Assumptions!$B$26/1024))*(Assumptions!$B$21/30.44)*Assumptions!$B$36-(($A10*(Assumptions!$B$23+Assumptions!$B$24+Assumptions!$B$25)/1024)+(Assumptions!$B$29*Assumptions!$B$26/1024))*Assumptions!$B$37-(($A10*Assumptions!$B$23/1024)*Assumptions!$B$31+($A10*Assumptions!$B$24/1024)*Assumptions!$B$32)*G$7
A11: 2000 | B11: =(Assumptions!$B$6*(1-Assumptions!$B$41-Assumptions!$B$43)-Assumptions!$B$42)-(Assumptions!$B$38+Assumptions!$B$39+Assumptions!$B$44*Assumptions!$B$45)-(($A11*(Assumptions!$B$23+Assumptions!$B$24+Assumptions!$B$25)/1024)+(Assumptions!$B$29*Assumptions!$B$26/1024))*((Assumptions!$B$16+Assumptions!$B$17+Assumptions!$B$18+Assumptions!$B$19)/30.44)*Assumptions!$B$34-(($A11*(Assumptions!$B$23+Assumptions!$B$24+Assumptions!$B$25)/1024)+(Assumptions!$B$29*Assumptions!$B$26/1024))*(Assumptions!$B$21/30.44)*Assumptions!$B$36-(($A11*(Assumptions!$B$23+Assumptions!$B$24+Assumptions!$B$25)/1024)+(Assumptions!$B$29*Assumptions!$B$26/1024))*Assumptions!$B$37-(($A11*Assumptions!$B$23/1024)*Assumptions!$B$31+($A11*Assumptions!$B$24/1024)*Assumptions!$B$32)*B$7 | C11: =(Assumptions!$B$6*(1-Assumptions!$B$41-Assumptions!$B$43)-Assumptions!$B$42)-(Assumptions!$B$38+Assumptions!$B$39+Assumptions!$B$44*Assumptions!$B$45)-(($A11*(Assumptions!$B$23+Assumptions!$B$24+Assumptions!$B$25)/1024)+(Assumptions!$B$29*Assumptions!$B$26/1024))*((Assumptions!$B$16+Assumptions!$B$17+Assumptions!$B$18+Assumptions!$B$19)/30.44)*Assumptions!$B$34-(($A11*(Assumptions!$B$23+Assumptions!$B$24+Assumptions!$B$25)/1024)+(Assumptions!$B$29*Assumptions!$B$26/1024))*(Assumptions!$B$21/30.44)*Assumptions!$B$36-(($A11*(Assumptions!$B$23+Assumptions!$B$24+Assumptions!$B$25)/1024)+(Assumptions!$B$29*Assumptions!$B$26/1024))*Assumptions!$B$37-(($A11*Assumptions!$B$23/1024)*Assumptions!$B$31+($A11*Assumptions!$B$24/1024)*Assumptions!$B$32)*C$7 | D11: =(Assumptions!$B$6*(1-Assumptions!$B$41-Assumptions!$B$43)-Assumptions!$B$42)-(Assumptions!$B$38+Assumptions!$B$39+Assumptions!$B$44*Assumptions!$B$45)-(($A11*(Assumptions!$B$23+Assumptions!$B$24+Assumptions!$B$25)/1024)+(Assumptions!$B$29*Assumptions!$B$26/1024))*((Assumptions!$B$16+Assumptions!$B$17+Assumptions!$B$18+Assumptions!$B$19)/30.44)*Assumptions!$B$34-(($A11*(Assumptions!$B$23+Assumptions!$B$24+Assumptions!$B$25)/1024)+(Assumptions!$B$29*Assumptions!$B$26/1024))*(Assumptions!$B$21/30.44)*Assumptions!$B$36-(($A11*(Assumptions!$B$23+Assumptions!$B$24+Assumptions!$B$25)/1024)+(Assumptions!$B$29*Assumptions!$B$26/1024))*Assumptions!$B$37-(($A11*Assumptions!$B$23/1024)*Assumptions!$B$31+($A11*Assumptions!$B$24/1024)*Assumptions!$B$32)*D$7 | E11: =(Assumptions!$B$6*(1-Assumptions!$B$41-Assumptions!$B$43)-Assumptions!$B$42)-(Assumptions!$B$38+Assumptions!$B$39+Assumptions!$B$44*Assumptions!$B$45)-(($A11*(Assumptions!$B$23+Assumptions!$B$24+Assumptions!$B$25)/1024)+(Assumptions!$B$29*Assumptions!$B$26/1024))*((Assumptions!$B$16+Assumptions!$B$17+Assumptions!$B$18+Assumptions!$B$19)/30.44)*Assumptions!$B$34-(($A11*(Assumptions!$B$23+Assumptions!$B$24+Assumptions!$B$25)/1024)+(Assumptions!$B$29*Assumptions!$B$26/1024))*(Assumptions!$B$21/30.44)*Assumptions!$B$36-(($A11*(Assumptions!$B$23+Assumptions!$B$24+Assumptions!$B$25)/1024)+(Assumptions!$B$29*Assumptions!$B$26/1024))*Assumptions!$B$37-(($A11*Assumptions!$B$23/1024)*Assumptions!$B$31+($A11*Assumptions!$B$24/1024)*Assumptions!$B$32)*E$7 | F11: =(Assumptions!$B$6*(1-Assumptions!$B$41-Assumptions!$B$43)-Assumptions!$B$42)-(Assumptions!$B$38+Assumptions!$B$39+Assumptions!$B$44*Assumptions!$B$45)-(($A11*(Assumptions!$B$23+Assumptions!$B$24+Assumptions!$B$25)/1024)+(Assumptions!$B$29*Assumptions!$B$26/1024))*((Assumptions!$B$16+Assumptions!$B$17+Assumptions!$B$18+Assumptions!$B$19)/30.44)*Assumptions!$B$34-(($A11*(Assumptions!$B$23+Assumptions!$B$24+Assumptions!$B$25)/1024)+(Assumptions!$B$29*Assumptions!$B$26/1024))*(Assumptions!$B$21/30.44)*Assumptions!$B$36-(($A11*(Assumptions!$B$23+Assumptions!$B$24+Assumptions!$B$25)/1024)+(Assumptions!$B$29*Assumptions!$B$26/1024))*Assumptions!$B$37-(($A11*Assumptions!$B$23/1024)*Assumptions!$B$31+($A11*Assumptions!$B$24/1024)*Assumptions!$B$32)*F$7 | G11: =(Assumptions!$B$6*(1-Assumptions!$B$41-Assumptions!$B$43)-Assumptions!$B$42)-(Assumptions!$B$38+Assumptions!$B$39+Assumptions!$B$44*Assumptions!$B$45)-(($A11*(Assumptions!$B$23+Assumptions!$B$24+Assumptions!$B$25)/1024)+(Assumptions!$B$29*Assumptions!$B$26/1024))*((Assumptions!$B$16+Assumptions!$B$17+Assumptions!$B$18+Assumptions!$B$19)/30.44)*Assumptions!$B$34-(($A11*(Assumptions!$B$23+Assumptions!$B$24+Assumptions!$B$25)/1024)+(Assumptions!$B$29*Assumptions!$B$26/1024))*(Assumptions!$B$21/30.44)*Assumptions!$B$36-(($A11*(Assumptions!$B$23+Assumptions!$B$24+Assumptions!$B$25)/1024)+(Assumptions!$B$29*Assumptions!$B$26/1024))*Assumptions!$B$37-(($A11*Assumptions!$B$23/1024)*Assumptions!$B$31+($A11*Assumptions!$B$24/1024)*Assumptions!$B$32)*G$7
A12: 3000 | B12: =(Assumptions!$B$6*(1-Assumptions!$B$41-Assumptions!$B$43)-Assumptions!$B$42)-(Assumptions!$B$38+Assumptions!$B$39+Assumptions!$B$44*Assumptions!$B$45)-(($A12*(Assumptions!$B$23+Assumptions!$B$24+Assumptions!$B$25)/1024)+(Assumptions!$B$29*Assumptions!$B$26/1024))*((Assumptions!$B$16+Assumptions!$B$17+Assumptions!$B$18+Assumptions!$B$19)/30.44)*Assumptions!$B$34-(($A12*(Assumptions!$B$23+Assumptions!$B$24+Assumptions!$B$25)/1024)+(Assumptions!$B$29*Assumptions!$B$26/1024))*(Assumptions!$B$21/30.44)*Assumptions!$B$36-(($A12*(Assumptions!$B$23+Assumptions!$B$24+Assumptions!$B$25)/1024)+(Assumptions!$B$29*Assumptions!$B$26/1024))*Assumptions!$B$37-(($A12*Assumptions!$B$23/1024)*Assumptions!$B$31+($A12*Assumptions!$B$24/1024)*Assumptions!$B$32)*B$7 | C12: =(Assumptions!$B$6*(1-Assumptions!$B$41-Assumptions!$B$43)-Assumptions!$B$42)-(Assumptions!$B$38+Assumptions!$B$39+Assumptions!$B$44*Assumptions!$B$45)-(($A12*(Assumptions!$B$23+Assumptions!$B$24+Assumptions!$B$25)/1024)+(Assumptions!$B$29*Assumptions!$B$26/1024))*((Assumptions!$B$16+Assumptions!$B$17+Assumptions!$B$18+Assumptions!$B$19)/30.44)*Assumptions!$B$34-(($A12*(Assumptions!$B$23+Assumptions!$B$24+Assumptions!$B$25)/1024)+(Assumptions!$B$29*Assumptions!$B$26/1024))*(Assumptions!$B$21/30.44)*Assumptions!$B$36-(($A12*(Assumptions!$B$23+Assumptions!$B$24+Assumptions!$B$25)/1024)+(Assumptions!$B$29*Assumptions!$B$26/1024))*Assumptions!$B$37-(($A12*Assumptions!$B$23/1024)*Assumptions!$B$31+($A12*Assumptions!$B$24/1024)*Assumptions!$B$32)*C$7 | D12: =(Assumptions!$B$6*(1-Assumptions!$B$41-Assumptions!$B$43)-Assumptions!$B$42)-(Assumptions!$B$38+Assumptions!$B$39+Assumptions!$B$44*Assumptions!$B$45)-(($A12*(Assumptions!$B$23+Assumptions!$B$24+Assumptions!$B$25)/1024)+(Assumptions!$B$29*Assumptions!$B$26/1024))*((Assumptions!$B$16+Assumptions!$B$17+Assumptions!$B$18+Assumptions!$B$19)/30.44)*Assumptions!$B$34-(($A12*(Assumptions!$B$23+Assumptions!$B$24+Assumptions!$B$25)/1024)+(Assumptions!$B$29*Assumptions!$B$26/1024))*(Assumptions!$B$21/30.44)*Assumptions!$B$36-(($A12*(Assumptions!$B$23+Assumptions!$B$24+Assumptions!$B$25)/1024)+(Assumptions!$B$29*Assumptions!$B$26/1024))*Assumptions!$B$37-(($A12*Assumptions!$B$23/1024)*Assumptions!$B$31+($A12*Assumptions!$B$24/1024)*Assumptions!$B$32)*D$7 | E12: =(Assumptions!$B$6*(1-Assumptions!$B$41-Assumptions!$B$43)-Assumptions!$B$42)-(Assumptions!$B$38+Assumptions!$B$39+Assumptions!$B$44*Assumptions!$B$45)-(($A12*(Assumptions!$B$23+Assumptions!$B$24+Assumptions!$B$25)/1024)+(Assumptions!$B$29*Assumptions!$B$26/1024))*((Assumptions!$B$16+Assumptions!$B$17+Assumptions!$B$18+Assumptions!$B$19)/30.44)*Assumptions!$B$34-(($A12*(Assumptions!$B$23+Assumptions!$B$24+Assumptions!$B$25)/1024)+(Assumptions!$B$29*Assumptions!$B$26/1024))*(Assumptions!$B$21/30.44)*Assumptions!$B$36-(($A12*(Assumptions!$B$23+Assumptions!$B$24+Assumptions!$B$25)/1024)+(Assumptions!$B$29*Assumptions!$B$26/1024))*Assumptions!$B$37-(($A12*Assumptions!$B$23/1024)*Assumptions!$B$31+($A12*Assumptions!$B$24/1024)*Assumptions!$B$32)*E$7 | F12: =(Assumptions!$B$6*(1-Assumptions!$B$41-Assumptions!$B$43)-Assumptions!$B$42)-(Assumptions!$B$38+Assumptions!$B$39+Assumptions!$B$44*Assumptions!$B$45)-(($A12*(Assumptions!$B$23+Assumptions!$B$24+Assumptions!$B$25)/1024)+(Assumptions!$B$29*Assumptions!$B$26/1024))*((Assumptions!$B$16+Assumptions!$B$17+Assumptions!$B$18+Assumptions!$B$19)/30.44)*Assumptions!$B$34-(($A12*(Assumptions!$B$23+Assumptions!$B$24+Assumptions!$B$25)/1024)+(Assumptions!$B$29*Assumptions!$B$26/1024))*(Assumptions!$B$21/30.44)*Assumptions!$B$36-(($A12*(Assumptions!$B$23+Assumptions!$B$24+Assumptions!$B$25)/1024)+(Assumptions!$B$29*Assumptions!$B$26/1024))*Assumptions!$B$37-(($A12*Assumptions!$B$23/1024)*Assumptions!$B$31+($A12*Assumptions!$B$24/1024)*Assumptions!$B$32)*F$7 | G12: =(Assumptions!$B$6*(1-Assumptions!$B$41-Assumptions!$B$43)-Assumptions!$B$42)-(Assumptions!$B$38+Assumptions!$B$39+Assumptions!$B$44*Assumptions!$B$45)-(($A12*(Assumptions!$B$23+Assumptions!$B$24+Assumptions!$B$25)/1024)+(Assumptions!$B$29*Assumptions!$B$26/1024))*((Assumptions!$B$16+Assumptions!$B$17+Assumptions!$B$18+Assumptions!$B$19)/30.44)*Assumptions!$B$34-(($A12*(Assumptions!$B$23+Assumptions!$B$24+Assumptions!$B$25)/1024)+(Assumptions!$B$29*Assumptions!$B$26/1024))*(Assumptions!$B$21/30.44)*Assumptions!$B$36-(($A12*(Assumptions!$B$23+Assumptions!$B$24+Assumptions!$B$25)/1024)+(Assumptions!$B$29*Assumptions!$B$26/1024))*Assumptions!$B$37-(($A12*Assumptions!$B$23/1024)*Assumptions!$B$31+($A12*Assumptions!$B$24/1024)*Assumptions!$B$32)*G$7
A13: 5000 | B13: =(Assumptions!$B$6*(1-Assumptions!$B$41-Assumptions!$B$43)-Assumptions!$B$42)-(Assumptions!$B$38+Assumptions!$B$39+Assumptions!$B$44*Assumptions!$B$45)-(($A13*(Assumptions!$B$23+Assumptions!$B$24+Assumptions!$B$25)/1024)+(Assumptions!$B$29*Assumptions!$B$26/1024))*((Assumptions!$B$16+Assumptions!$B$17+Assumptions!$B$18+Assumptions!$B$19)/30.44)*Assumptions!$B$34-(($A13*(Assumptions!$B$23+Assumptions!$B$24+Assumptions!$B$25)/1024)+(Assumptions!$B$29*Assumptions!$B$26/1024))*(Assumptions!$B$21/30.44)*Assumptions!$B$36-(($A13*(Assumptions!$B$23+Assumptions!$B$24+Assumptions!$B$25)/1024)+(Assumptions!$B$29*Assumptions!$B$26/1024))*Assumptions!$B$37-(($A13*Assumptions!$B$23/1024)*Assumptions!$B$31+($A13*Assumptions!$B$24/1024)*Assumptions!$B$32)*B$7 | C13: =(Assumptions!$B$6*(1-Assumptions!$B$41-Assumptions!$B$43)-Assumptions!$B$42)-(Assumptions!$B$38+Assumptions!$B$39+Assumptions!$B$44*Assumptions!$B$45)-(($A13*(Assumptions!$B$23+Assumptions!$B$24+Assumptions!$B$25)/1024)+(Assumptions!$B$29*Assumptions!$B$26/1024))*((Assumptions!$B$16+Assumptions!$B$17+Assumptions!$B$18+Assumptions!$B$19)/30.44)*Assumptions!$B$34-(($A13*(Assumptions!$B$23+Assumptions!$B$24+Assumptions!$B$25)/1024)+(Assumptions!$B$29*Assumptions!$B$26/1024))*(Assumptions!$B$21/30.44)*Assumptions!$B$36-(($A13*(Assumptions!$B$23+Assumptions!$B$24+Assumptions!$B$25)/1024)+(Assumptions!$B$29*Assumptions!$B$26/1024))*Assumptions!$B$37-(($A13*Assumptions!$B$23/1024)*Assumptions!$B$31+($A13*Assumptions!$B$24/1024)*Assumptions!$B$32)*C$7 | D13: =(Assumptions!$B$6*(1-Assumptions!$B$41-Assumptions!$B$43)-Assumptions!$B$42)-(Assumptions!$B$38+Assumptions!$B$39+Assumptions!$B$44*Assumptions!$B$45)-(($A13*(Assumptions!$B$23+Assumptions!$B$24+Assumptions!$B$25)/1024)+(Assumptions!$B$29*Assumptions!$B$26/1024))*((Assumptions!$B$16+Assumptions!$B$17+Assumptions!$B$18+Assumptions!$B$19)/30.44)*Assumptions!$B$34-(($A13*(Assumptions!$B$23+Assumptions!$B$24+Assumptions!$B$25)/1024)+(Assumptions!$B$29*Assumptions!$B$26/1024))*(Assumptions!$B$21/30.44)*Assumptions!$B$36-(($A13*(Assumptions!$B$23+Assumptions!$B$24+Assumptions!$B$25)/1024)+(Assumptions!$B$29*Assumptions!$B$26/1024))*Assumptions!$B$37-(($A13*Assumptions!$B$23/1024)*Assumptions!$B$31+($A13*Assumptions!$B$24/1024)*Assumptions!$B$32)*D$7 | E13: =(Assumptions!$B$6*(1-Assumptions!$B$41-Assumptions!$B$43)-Assumptions!$B$42)-(Assumptions!$B$38+Assumptions!$B$39+Assumptions!$B$44*Assumptions!$B$45)-(($A13*(Assumptions!$B$23+Assumptions!$B$24+Assumptions!$B$25)/1024)+(Assumptions!$B$29*Assumptions!$B$26/1024))*((Assumptions!$B$16+Assumptions!$B$17+Assumptions!$B$18+Assumptions!$B$19)/30.44)*Assumptions!$B$34-(($A13*(Assumptions!$B$23+Assumptions!$B$24+Assumptions!$B$25)/1024)+(Assumptions!$B$29*Assumptions!$B$26/1024))*(Assumptions!$B$21/30.44)*Assumptions!$B$36-(($A13*(Assumptions!$B$23+Assumptions!$B$24+Assumptions!$B$25)/1024)+(Assumptions!$B$29*Assumptions!$B$26/1024))*Assumptions!$B$37-(($A13*Assumptions!$B$23/1024)*Assumptions!$B$31+($A13*Assumptions!$B$24/1024)*Assumptions!$B$32)*E$7 | F13: =(Assumptions!$B$6*(1-Assumptions!$B$41-Assumptions!$B$43)-Assumptions!$B$42)-(Assumptions!$B$38+Assumptions!$B$39+Assumptions!$B$44*Assumptions!$B$45)-(($A13*(Assumptions!$B$23+Assumptions!$B$24+Assumptions!$B$25)/1024)+(Assumptions!$B$29*Assumptions!$B$26/1024))*((Assumptions!$B$16+Assumptions!$B$17+Assumptions!$B$18+Assumptions!$B$19)/30.44)*Assumptions!$B$34-(($A13*(Assumptions!$B$23+Assumptions!$B$24+Assumptions!$B$25)/1024)+(Assumptions!$B$29*Assumptions!$B$26/1024))*(Assumptions!$B$21/30.44)*Assumptions!$B$36-(($A13*(Assumptions!$B$23+Assumptions!$B$24+Assumptions!$B$25)/1024)+(Assumptions!$B$29*Assumptions!$B$26/1024))*Assumptions!$B$37-(($A13*Assumptions!$B$23/1024)*Assumptions!$B$31+($A13*Assumptions!$B$24/1024)*Assumptions!$B$32)*F$7 | G13: =(Assumptions!$B$6*(1-Assumptions!$B$41-Assumptions!$B$43)-Assumptions!$B$42)-(Assumptions!$B$38+Assumptions!$B$39+Assumptions!$B$44*Assumptions!$B$45)-(($A13*(Assumptions!$B$23+Assumptions!$B$24+Assumptions!$B$25)/1024)+(Assumptions!$B$29*Assumptions!$B$26/1024))*((Assumptions!$B$16+Assumptions!$B$17+Assumptions!$B$18+Assumptions!$B$19)/30.44)*Assumptions!$B$34-(($A13*(Assumptions!$B$23+Assumptions!$B$24+Assumptions!$B$25)/1024)+(Assumptions!$B$29*Assumptions!$B$26/1024))*(Assumptions!$B$21/30.44)*Assumptions!$B$36-(($A13*(Assumptions!$B$23+Assumptions!$B$24+Assumptions!$B$25)/1024)+(Assumptions!$B$29*Assumptions!$B$26/1024))*Assumptions!$B$37-(($A13*Assumptions!$B$23/1024)*Assumptions!$B$31+($A13*Assumptions!$B$24/1024)*Assumptions!$B$32)*G$7
A14: 10000 | B14: =(Assumptions!$B$6*(1-Assumptions!$B$41-Assumptions!$B$43)-Assumptions!$B$42)-(Assumptions!$B$38+Assumptions!$B$39+Assumptions!$B$44*Assumptions!$B$45)-(($A14*(Assumptions!$B$23+Assumptions!$B$24+Assumptions!$B$25)/1024)+(Assumptions!$B$29*Assumptions!$B$26/1024))*((Assumptions!$B$16+Assumptions!$B$17+Assumptions!$B$18+Assumptions!$B$19)/30.44)*Assumptions!$B$34-(($A14*(Assumptions!$B$23+Assumptions!$B$24+Assumptions!$B$25)/1024)+(Assumptions!$B$29*Assumptions!$B$26/1024))*(Assumptions!$B$21/30.44)*Assumptions!$B$36-(($A14*(Assumptions!$B$23+Assumptions!$B$24+Assumptions!$B$25)/1024)+(Assumptions!$B$29*Assumptions!$B$26/1024))*Assumptions!$B$37-(($A14*Assumptions!$B$23/1024)*Assumptions!$B$31+($A14*Assumptions!$B$24/1024)*Assumptions!$B$32)*B$7 | C14: =(Assumptions!$B$6*(1-Assumptions!$B$41-Assumptions!$B$43)-Assumptions!$B$42)-(Assumptions!$B$38+Assumptions!$B$39+Assumptions!$B$44*Assumptions!$B$45)-(($A14*(Assumptions!$B$23+Assumptions!$B$24+Assumptions!$B$25)/1024)+(Assumptions!$B$29*Assumptions!$B$26/1024))*((Assumptions!$B$16+Assumptions!$B$17+Assumptions!$B$18+Assumptions!$B$19)/30.44)*Assumptions!$B$34-(($A14*(Assumptions!$B$23+Assumptions!$B$24+Assumptions!$B$25)/1024)+(Assumptions!$B$29*Assumptions!$B$26/1024))*(Assumptions!$B$21/30.44)*Assumptions!$B$36-(($A14*(Assumptions!$B$23+Assumptions!$B$24+Assumptions!$B$25)/1024)+(Assumptions!$B$29*Assumptions!$B$26/1024))*Assumptions!$B$37-(($A14*Assumptions!$B$23/1024)*Assumptions!$B$31+($A14*Assumptions!$B$24/1024)*Assumptions!$B$32)*C$7 | D14: =(Assumptions!$B$6*(1-Assumptions!$B$41-Assumptions!$B$43)-Assumptions!$B$42)-(Assumptions!$B$38+Assumptions!$B$39+Assumptions!$B$44*Assumptions!$B$45)-(($A14*(Assumptions!$B$23+Assumptions!$B$24+Assumptions!$B$25)/1024)+(Assumptions!$B$29*Assumptions!$B$26/1024))*((Assumptions!$B$16+Assumptions!$B$17+Assumptions!$B$18+Assumptions!$B$19)/30.44)*Assumptions!$B$34-(($A14*(Assumptions!$B$23+Assumptions!$B$24+Assumptions!$B$25)/1024)+(Assumptions!$B$29*Assumptions!$B$26/1024))*(Assumptions!$B$21/30.44)*Assumptions!$B$36-(($A14*(Assumptions!$B$23+Assumptions!$B$24+Assumptions!$B$25)/1024)+(Assumptions!$B$29*Assumptions!$B$26/1024))*Assumptions!$B$37-(($A14*Assumptions!$B$23/1024)*Assumptions!$B$31+($A14*Assumptions!$B$24/1024)*Assumptions!$B$32)*D$7 | E14: =(Assumptions!$B$6*(1-Assumptions!$B$41-Assumptions!$B$43)-Assumptions!$B$42)-(Assumptions!$B$38+Assumptions!$B$39+Assumptions!$B$44*Assumptions!$B$45)-(($A14*(Assumptions!$B$23+Assumptions!$B$24+Assumptions!$B$25)/1024)+(Assumptions!$B$29*Assumptions!$B$26/1024))*((Assumptions!$B$16+Assumptions!$B$17+Assumptions!$B$18+Assumptions!$B$19)/30.44)*Assumptions!$B$34-(($A14*(Assumptions!$B$23+Assumptions!$B$24+Assumptions!$B$25)/1024)+(Assumptions!$B$29*Assumptions!$B$26/1024))*(Assumptions!$B$21/30.44)*Assumptions!$B$36-(($A14*(Assumptions!$B$23+Assumptions!$B$24+Assumptions!$B$25)/1024)+(Assumptions!$B$29*Assumptions!$B$26/1024))*Assumptions!$B$37-(($A14*Assumptions!$B$23/1024)*Assumptions!$B$31+($A14*Assumptions!$B$24/1024)*Assumptions!$B$32)*E$7 | F14: =(Assumptions!$B$6*(1-Assumptions!$B$41-Assumptions!$B$43)-Assumptions!$B$42)-(Assumptions!$B$38+Assumptions!$B$39+Assumptions!$B$44*Assumptions!$B$45)-(($A14*(Assumptions!$B$23+Assumptions!$B$24+Assumptions!$B$25)/1024)+(Assumptions!$B$29*Assumptions!$B$26/1024))*((Assumptions!$B$16+Assumptions!$B$17+Assumptions!$B$18+Assumptions!$B$19)/30.44)*Assumptions!$B$34-(($A14*(Assumptions!$B$23+Assumptions!$B$24+Assumptions!$B$25)/1024)+(Assumptions!$B$29*Assumptions!$B$26/1024))*(Assumptions!$B$21/30.44)*Assumptions!$B$36-(($A14*(Assumptions!$B$23+Assumptions!$B$24+Assumptions!$B$25)/1024)+(Assumptions!$B$29*Assumptions!$B$26/1024))*Assumptions!$B$37-(($A14*Assumptions!$B$23/1024)*Assumptions!$B$31+($A14*Assumptions!$B$24/1024)*Assumptions!$B$32)*F$7 | G14: =(Assumptions!$B$6*(1-Assumptions!$B$41-Assumptions!$B$43)-Assumptions!$B$42)-(Assumptions!$B$38+Assumptions!$B$39+Assumptions!$B$44*Assumptions!$B$45)-(($A14*(Assumptions!$B$23+Assumptions!$B$24+Assumptions!$B$25)/1024)+(Assumptions!$B$29*Assumptions!$B$26/1024))*((Assumptions!$B$16+Assumptions!$B$17+Assumptions!$B$18+Assumptions!$B$19)/30.44)*Assumptions!$B$34-(($A14*(Assumptions!$B$23+Assumptions!$B$24+Assumptions!$B$25)/1024)+(Assumptions!$B$29*Assumptions!$B$26/1024))*(Assumptions!$B$21/30.44)*Assumptions!$B$36-(($A14*(Assumptions!$B$23+Assumptions!$B$24+Assumptions!$B$25)/1024)+(Assumptions!$B$29*Assumptions!$B$26/1024))*Assumptions!$B$37-(($A14*Assumptions!$B$23/1024)*Assumptions!$B$31+($A14*Assumptions!$B$24/1024)*Assumptions!$B$32)*G$7
A15: 20000 | B15: =(Assumptions!$B$6*(1-Assumptions!$B$41-Assumptions!$B$43)-Assumptions!$B$42)-(Assumptions!$B$38+Assumptions!$B$39+Assumptions!$B$44*Assumptions!$B$45)-(($A15*(Assumptions!$B$23+Assumptions!$B$24+Assumptions!$B$25)/1024)+(Assumptions!$B$29*Assumptions!$B$26/1024))*((Assumptions!$B$16+Assumptions!$B$17+Assumptions!$B$18+Assumptions!$B$19)/30.44)*Assumptions!$B$34-(($A15*(Assumptions!$B$23+Assumptions!$B$24+Assumptions!$B$25)/1024)+(Assumptions!$B$29*Assumptions!$B$26/1024))*(Assumptions!$B$21/30.44)*Assumptions!$B$36-(($A15*(Assumptions!$B$23+Assumptions!$B$24+Assumptions!$B$25)/1024)+(Assumptions!$B$29*Assumptions!$B$26/1024))*Assumptions!$B$37-(($A15*Assumptions!$B$23/1024)*Assumptions!$B$31+($A15*Assumptions!$B$24/1024)*Assumptions!$B$32)*B$7 | C15: =(Assumptions!$B$6*(1-Assumptions!$B$41-Assumptions!$B$43)-Assumptions!$B$42)-(Assumptions!$B$38+Assumptions!$B$39+Assumptions!$B$44*Assumptions!$B$45)-(($A15*(Assumptions!$B$23+Assumptions!$B$24+Assumptions!$B$25)/1024)+(Assumptions!$B$29*Assumptions!$B$26/1024))*((Assumptions!$B$16+Assumptions!$B$17+Assumptions!$B$18+Assumptions!$B$19)/30.44)*Assumptions!$B$34-(($A15*(Assumptions!$B$23+Assumptions!$B$24+Assumptions!$B$25)/1024)+(Assumptions!$B$29*Assumptions!$B$26/1024))*(Assumptions!$B$21/30.44)*Assumptions!$B$36-(($A15*(Assumptions!$B$23+Assumptions!$B$24+Assumptions!$B$25)/1024)+(Assumptions!$B$29*Assumptions!$B$26/1024))*Assumptions!$B$37-(($A15*Assumptions!$B$23/1024)*Assumptions!$B$31+($A15*Assumptions!$B$24/1024)*Assumptions!$B$32)*C$7 | D15: =(Assumptions!$B$6*(1-Assumptions!$B$41-Assumptions!$B$43)-Assumptions!$B$42)-(Assumptions!$B$38+Assumptions!$B$39+Assumptions!$B$44*Assumptions!$B$45)-(($A15*(Assumptions!$B$23+Assumptions!$B$24+Assumptions!$B$25)/1024)+(Assumptions!$B$29*Assumptions!$B$26/1024))*((Assumptions!$B$16+Assumptions!$B$17+Assumptions!$B$18+Assumptions!$B$19)/30.44)*Assumptions!$B$34-(($A15*(Assumptions!$B$23+Assumptions!$B$24+Assumptions!$B$25)/1024)+(Assumptions!$B$29*Assumptions!$B$26/1024))*(Assumptions!$B$21/30.44)*Assumptions!$B$36-(($A15*(Assumptions!$B$23+Assumptions!$B$24+Assumptions!$B$25)/1024)+(Assumptions!$B$29*Assumptions!$B$26/1024))*Assumptions!$B$37-(($A15*Assumptions!$B$23/1024)*Assumptions!$B$31+($A15*Assumptions!$B$24/1024)*Assumptions!$B$32)*D$7 | E15: =(Assumptions!$B$6*(1-Assumptions!$B$41-Assumptions!$B$43)-Assumptions!$B$42)-(Assumptions!$B$38+Assumptions!$B$39+Assumptions!$B$44*Assumptions!$B$45)-(($A15*(Assumptions!$B$23+Assumptions!$B$24+Assumptions!$B$25)/1024)+(Assumptions!$B$29*Assumptions!$B$26/1024))*((Assumptions!$B$16+Assumptions!$B$17+Assumptions!$B$18+Assumptions!$B$19)/30.44)*Assumptions!$B$34-(($A15*(Assumptions!$B$23+Assumptions!$B$24+Assumptions!$B$25)/1024)+(Assumptions!$B$29*Assumptions!$B$26/1024))*(Assumptions!$B$21/30.44)*Assumptions!$B$36-(($A15*(Assumptions!$B$23+Assumptions!$B$24+Assumptions!$B$25)/1024)+(Assumptions!$B$29*Assumptions!$B$26/1024))*Assumptions!$B$37-(($A15*Assumptions!$B$23/1024)*Assumptions!$B$31+($A15*Assumptions!$B$24/1024)*Assumptions!$B$32)*E$7 | F15: =(Assumptions!$B$6*(1-Assumptions!$B$41-Assumptions!$B$43)-Assumptions!$B$42)-(Assumptions!$B$38+Assumptions!$B$39+Assumptions!$B$44*Assumptions!$B$45)-(($A15*(Assumptions!$B$23+Assumptions!$B$24+Assumptions!$B$25)/1024)+(Assumptions!$B$29*Assumptions!$B$26/1024))*((Assumptions!$B$16+Assumptions!$B$17+Assumptions!$B$18+Assumptions!$B$19)/30.44)*Assumptions!$B$34-(($A15*(Assumptions!$B$23+Assumptions!$B$24+Assumptions!$B$25)/1024)+(Assumptions!$B$29*Assumptions!$B$26/1024))*(Assumptions!$B$21/30.44)*Assumptions!$B$36-(($A15*(Assumptions!$B$23+Assumptions!$B$24+Assumptions!$B$25)/1024)+(Assumptions!$B$29*Assumptions!$B$26/1024))*Assumptions!$B$37-(($A15*Assumptions!$B$23/1024)*Assumptions!$B$31+($A15*Assumptions!$B$24/1024)*Assumptions!$B$32)*F$7 | G15: =(Assumptions!$B$6*(1-Assumptions!$B$41-Assumptions!$B$43)-Assumptions!$B$42)-(Assumptions!$B$38+Assumptions!$B$39+Assumptions!$B$44*Assumptions!$B$45)-(($A15*(Assumptions!$B$23+Assumptions!$B$24+Assumptions!$B$25)/1024)+(Assumptions!$B$29*Assumptions!$B$26/1024))*((Assumptions!$B$16+Assumptions!$B$17+Assumptions!$B$18+Assumptions!$B$19)/30.44)*Assumptions!$B$34-(($A15*(Assumptions!$B$23+Assumptions!$B$24+Assumptions!$B$25)/1024)+(Assumptions!$B$29*Assumptions!$B$26/1024))*(Assumptions!$B$21/30.44)*Assumptions!$B$36-(($A15*(Assumptions!$B$23+Assumptions!$B$24+Assumptions!$B$25)/1024)+(Assumptions!$B$29*Assumptions!$B$26/1024))*Assumptions!$B$37-(($A15*Assumptions!$B$23/1024)*Assumptions!$B$31+($A15*Assumptions!$B$24/1024)*Assumptions!$B$32)*G$7
A16: 50000 | B16: =(Assumptions!$B$6*(1-Assumptions!$B$41-Assumptions!$B$43)-Assumptions!$B$42)-(Assumptions!$B$38+Assumptions!$B$39+Assumptions!$B$44*Assumptions!$B$45)-(($A16*(Assumptions!$B$23+Assumptions!$B$24+Assumptions!$B$25)/1024)+(Assumptions!$B$29*Assumptions!$B$26/1024))*((Assumptions!$B$16+Assumptions!$B$17+Assumptions!$B$18+Assumptions!$B$19)/30.44)*Assumptions!$B$34-(($A16*(Assumptions!$B$23+Assumptions!$B$24+Assumptions!$B$25)/1024)+(Assumptions!$B$29*Assumptions!$B$26/1024))*(Assumptions!$B$21/30.44)*Assumptions!$B$36-(($A16*(Assumptions!$B$23+Assumptions!$B$24+Assumptions!$B$25)/1024)+(Assumptions!$B$29*Assumptions!$B$26/1024))*Assumptions!$B$37-(($A16*Assumptions!$B$23/1024)*Assumptions!$B$31+($A16*Assumptions!$B$24/1024)*Assumptions!$B$32)*B$7 | C16: =(Assumptions!$B$6*(1-Assumptions!$B$41-Assumptions!$B$43)-Assumptions!$B$42)-(Assumptions!$B$38+Assumptions!$B$39+Assumptions!$B$44*Assumptions!$B$45)-(($A16*(Assumptions!$B$23+Assumptions!$B$24+Assumptions!$B$25)/1024)+(Assumptions!$B$29*Assumptions!$B$26/1024))*((Assumptions!$B$16+Assumptions!$B$17+Assumptions!$B$18+Assumptions!$B$19)/30.44)*Assumptions!$B$34-(($A16*(Assumptions!$B$23+Assumptions!$B$24+Assumptions!$B$25)/1024)+(Assumptions!$B$29*Assumptions!$B$26/1024))*(Assumptions!$B$21/30.44)*Assumptions!$B$36-(($A16*(Assumptions!$B$23+Assumptions!$B$24+Assumptions!$B$25)/1024)+(Assumptions!$B$29*Assumptions!$B$26/1024))*Assumptions!$B$37-(($A16*Assumptions!$B$23/1024)*Assumptions!$B$31+($A16*Assumptions!$B$24/1024)*Assumptions!$B$32)*C$7 | D16: =(Assumptions!$B$6*(1-Assumptions!$B$41-Assumptions!$B$43)-Assumptions!$B$42)-(Assumptions!$B$38+Assumptions!$B$39+Assumptions!$B$44*Assumptions!$B$45)-(($A16*(Assumptions!$B$23+Assumptions!$B$24+Assumptions!$B$25)/1024)+(Assumptions!$B$29*Assumptions!$B$26/1024))*((Assumptions!$B$16+Assumptions!$B$17+Assumptions!$B$18+Assumptions!$B$19)/30.44)*Assumptions!$B$34-(($A16*(Assumptions!$B$23+Assumptions!$B$24+Assumptions!$B$25)/1024)+(Assumptions!$B$29*Assumptions!$B$26/1024))*(Assumptions!$B$21/30.44)*Assumptions!$B$36-(($A16*(Assumptions!$B$23+Assumptions!$B$24+Assumptions!$B$25)/1024)+(Assumptions!$B$29*Assumptions!$B$26/1024))*Assumptions!$B$37-(($A16*Assumptions!$B$23/1024)*Assumptions!$B$31+($A16*Assumptions!$B$24/1024)*Assumptions!$B$32)*D$7 | E16: =(Assumptions!$B$6*(1-Assumptions!$B$41-Assumptions!$B$43)-Assumptions!$B$42)-(Assumptions!$B$38+Assumptions!$B$39+Assumptions!$B$44*Assumptions!$B$45)-(($A16*(Assumptions!$B$23+Assumptions!$B$24+Assumptions!$B$25)/1024)+(Assumptions!$B$29*Assumptions!$B$26/1024))*((Assumptions!$B$16+Assumptions!$B$17+Assumptions!$B$18+Assumptions!$B$19)/30.44)*Assumptions!$B$34-(($A16*(Assumptions!$B$23+Assumptions!$B$24+Assumptions!$B$25)/1024)+(Assumptions!$B$29*Assumptions!$B$26/1024))*(Assumptions!$B$21/30.44)*Assumptions!$B$36-(($A16*(Assumptions!$B$23+Assumptions!$B$24+Assumptions!$B$25)/1024)+(Assumptions!$B$29*Assumptions!$B$26/1024))*Assumptions!$B$37-(($A16*Assumptions!$B$23/1024)*Assumptions!$B$31+($A16*Assumptions!$B$24/1024)*Assumptions!$B$32)*E$7 | F16: =(Assumptions!$B$6*(1-Assumptions!$B$41-Assumptions!$B$43)-Assumptions!$B$42)-(Assumptions!$B$38+Assumptions!$B$39+Assumptions!$B$44*Assumptions!$B$45)-(($A16*(Assumptions!$B$23+Assumptions!$B$24+Assumptions!$B$25)/1024)+(Assumptions!$B$29*Assumptions!$B$26/1024))*((Assumptions!$B$16+Assumptions!$B$17+Assumptions!$B$18+Assumptions!$B$19)/30.44)*Assumptions!$B$34-(($A16*(Assumptions!$B$23+Assumptions!$B$24+Assumptions!$B$25)/1024)+(Assumptions!$B$29*Assumptions!$B$26/1024))*(Assumptions!$B$21/30.44)*Assumptions!$B$36-(($A16*(Assumptions!$B$23+Assumptions!$B$24+Assumptions!$B$25)/1024)+(Assumptions!$B$29*Assumptions!$B$26/1024))*Assumptions!$B$37-(($A16*Assumptions!$B$23/1024)*Assumptions!$B$31+($A16*Assumptions!$B$24/1024)*Assumptions!$B$32)*F$7 | G16: =(Assumptions!$B$6*(1-Assumptions!$B$41-Assumptions!$B$43)-Assumptions!$B$42)-(Assumptions!$B$38+Assumptions!$B$39+Assumptions!$B$44*Assumptions!$B$45)-(($A16*(Assumptions!$B$23+Assumptions!$B$24+Assumptions!$B$25)/1024)+(Assumptions!$B$29*Assumptions!$B$26/1024))*((Assumptions!$B$16+Assumptions!$B$17+Assumptions!$B$18+Assumptions!$B$19)/30.44)*Assumptions!$B$34-(($A16*(Assumptions!$B$23+Assumptions!$B$24+Assumptions!$B$25)/1024)+(Assumptions!$B$29*Assumptions!$B$26/1024))*(Assumptions!$B$21/30.44)*Assumptions!$B$36-(($A16*(Assumptions!$B$23+Assumptions!$B$24+Assumptions!$B$25)/1024)+(Assumptions!$B$29*Assumptions!$B$26/1024))*Assumptions!$B$37-(($A16*Assumptions!$B$23/1024)*Assumptions!$B$31+($A16*Assumptions!$B$24/1024)*Assumptions!$B$32)*G$7
A18: Break-even photo count, at today's zero egress | B18: =((Assumptions!$B$6*(1-Assumptions!$B$41-Assumptions!$B$43)-Assumptions!$B$42)-(Assumptions!$B$38+Assumptions!$B$39+Assumptions!$B$44*Assumptions!$B$45)-(Assumptions!$B$29*Assumptions!$B$26/1024)*(((Assumptions!$B$16+Assumptions!$B$17+Assumptions!$B$18+Assumptions!$B$19)/30.44)*Assumptions!$B$34+(Assumptions!$B$21/30.44)*Assumptions!$B$36+Assumptions!$B$37))/(((Assumptions!$B$23+Assumptions!$B$24+Assumptions!$B$25)/1024)*(((Assumptions!$B$16+Assumptions!$B$17+Assumptions!$B$18+Assumptions!$B$19)/30.44)*Assumptions!$B$34+(Assumptions!$B$21/30.44)*Assumptions!$B$36+Assumptions!$B$37))
A20: Compare that against the fair-use thresholds
A21: Fair use: review threshold | B21: 5000 | C21: photoReviewThreshold. Flags for a look; blocks nothing. Unchanged
A22: Fair use: abuse threshold | B22: 36800 | C22: photoAbuseThreshold, now derived from break-even in lib/fairUse.ts
A23: Abuse threshold as a multiple of break-even | B23: =IFERROR(B22/B18,0) | C23: Above 1.0x, an event can lose money for a long time before anything stops it
A25: How to read it
A26: Blue cells are inputs. Column A is the photo count; row 7 is the egress rate each column uses.
A27: Red is a loss on that event. Green is $40+ of margin.
A29: The first column is reality today, and it is the flattest: R2 charges nothing for egress, so a wildly
A30: popular event costs almost exactly what a quiet one of the same size costs. That is the entire return on
A31: the hybrid architecture (docs/r2-hybrid.md) and it is why unlimited photos was safe to promise at all.
A33: The right-hand columns are the exposure. If R2 ever priced egress at S3 parity, the sums stop working at a
A34: far smaller event, and the plan would have to change rather than the thresholds. That is a business risk
A35: worth knowing the size of, not a reason to act today.
A37: What actually bites first is storage, and most of that is the DUPLICATE S3 copy rather than the copy being
A38: served. See "Dual storage" on the Unit economics sheet.

Sheet Blended
A1: Blended margin per paid event
A2: Free events cost real money and produce none. The honest figure is margin per SALE, after carrying them.
B4: Value | C4: Note
A5: Gross margin, one paid event | B5: ='Unit economics'!B37 | C5: From Unit economics, at the central case
A6: Free events carried per paid event | B6: =Assumptions!$B$46 | C6: The lever that matters most on this sheet, and the one with the least evidence behind it
A7: Cost of those free events | B7: =-B6*'Unit economics'!C34
A8: Blended margin per paid event | B8: =B5+B7
A9: Blended margin % | B9: =IFERROR(B8/'Unit economics'!B24,0)
A11: Free events a sale can carry before margin hits zero | B11: =IFERROR(B5/'Unit economics'!C34,0) | C11: If the real free-to-paid ratio is worse than this, the free tier is not a funnel, it is a subsidy
A13: What this does not include
A14: No customer acquisition cost. No ad spend is tracked, so any CAC here would be invented — the monthly report
A15: says the same thing in its "not measured" list rather than printing a zero.
A16: No support cost. There is no ticketing system to measure it with.
A17: No chargebacks. Stripe dispute data is not read back yet.
A18: No repeat purchase. Every event is modelled as a one-time sale, which is the pessimistic reading and the
A19: right default until there is evidence of repeats.
